Workbook

Sheet CHINA
A1: 44284 | B1: CHINA
B2: ST ROSE | C2: Freight | D2: =1500000/D4 -> 50 | E2: usd/cbm | F2: Yangtze River ports
A3: 264.172 | B3: SANTOS | C3: Freight | D3: =(+'Freight matrix'!J24)*A4 -> 43.395 | E3: usd/cbm
A4: 0.789 | C4: Volume | D4: 30000 | E4: cbm
C6: Basis | D6: 0.1 | E6: cpg
B7: US | C7: APR | D7: MAY | E7: JUN | F7: JUL | G7: AUG | H7: SEP | I7: OCT | J7: NOV | K7: DEC | L7: JAN | M7: FEB | N7: MAR
B8: CHIP | C8: =+'settlement day'!F9 -> 0 | D8: =+'settlement day'!G9 -> 0 | E8: =+'settlement day'!H9 -> 0 | F8: =+'settlement day'!I9 -> 0 | G8: =+'settlement day'!J9 -> 0 | H8: =+'settlement day'!K9 -> 0 | I8: =+'settlement day'!L9 -> 0 | J8: =+'settlement day'!M9 -> 0 | K8: =+'settlement day'!N9 -> 0
B10: FOB IMTT | C10: =+(C8+$D$6)*$A$3 -> 26.4172 | D10: =+(D8+$D$6)*$A$3 -> 26.4172 | E10: =+(E8+$D$6)*$A$3 -> 26.4172 | F10: =+(F8+$D$6)*$A$3 -> 26.4172 | G10: =+(G8+$D$6)*$A$3 -> 26.4172 | H10: =+(H8+$D$6)*$A$3 -> 26.4172 | I10: =+(I8+$D$6)*$A$3 -> 26.4172 | J10: =+(J8+$D$6)*$A$3 -> 26.4172 | K10: =+(K8+$D$6)*$A$3 -> 26.4172
B11: CIF China usd/cbm | C11: =+C10+$D$2 -> 76.4172 | D11: =+D10+$D$2 -> 76.4172 | E11: =+E10+$D$2 -> 76.4172 | F11: =+F10+$D$2 -> 76.4172 | G11: =+G10+$D$2 -> 76.4172 | H11: =+H10+$D$2 -> 76.4172 | I11: =+I10+$D$2 -> 76.4172 | J11: =+J10+$D$2 -> 76.4172 | K11: =+K10+$D$2 -> 76.4172
A12: 1.45 | B12: Import duty | C12: =+C11*$A$12 -> 110.80494 | D12: =+D11*$A$12 -> 110.80494 | E12: =+E11*$A$12 -> 110.80494 | F12: =+F11*$A$12 -> 110.80494 | G12: =+G11*$A$12 -> 110.80494 | H12: =+H11*$A$12 -> 110.80494 | I12: =+I11*$A$12 -> 110.80494 | J12: =+J11*$A$12 -> 110.80494 | K12: =+K11*$A$12 -> 110.80494
B14: CIF usd/mt | C14: =+C12/$A$4 -> 140.43719 | D14: =+D12/$A$4 -> 140.43719 | E14: =+E12/$A$4 -> 140.43719 | F14: =+F12/$A$4 -> 140.43719 | G14: =+G12/$A$4 -> 140.43719 | H14: =+H12/$A$4 -> 140.43719 | I14: =+I12/$A$4 -> 140.43719 | J14: =+J12/$A$4 -> 140.43719 | K14: =+K12/$A$4 -> 140.43719
A17: inland | B17: BRAZIL | C17: APR | D17: MAY | E17: JUN | F17: JUL | G17: AUG | H17: SEP | I17: OCT | J17: NOV | K17: DEC | L17: JAN | M17: FEB | N17: MAR
A18: =+'mkt data'!G6+'mkt data'!G8 -> 90 | B18: B3 | C18: =+'settlement day'!F13 -> 0 | D18: =+'settlement day'!G13 -> 0 | E18: =+'settlement day'!H13 -> 0 | F18: =+'settlement day'!I13 -> 0 | G18: =+'settlement day'!J13 -> 0 | H18: =+'settlement day'!K13 -> 0 | I18: =+'settlement day'!L13 -> 0 | J18: =+'settlement day'!M13 -> 0 | K18: =+'settlement day'!N13 -> 0
A19: brl/cbm | B19: BRL/USD | C19: =+D19 -> 0 | D19: =+'settlement day'!G30 -> 0 | E19: =+'settlement day'!H30 -> 0 | F19: =+'settlement day'!I30 -> 0 | G19: =+'settlement day'!J30 -> 0 | H19: =+'settlement day'!K30 -> 0 | I19: =+'settlement day'!L30 -> 0 | J19: =+'settlement day'!M30 -> 0 | K19: =+'settlement day'!N30 -> 0
B20: hydrous FOB BRZ | C20: =+(C18+$A$18)/C19 -> #DIV/0! | D20: =+(D18+$A$18)/D19 -> #DIV/0! | E20: =+(E18+$A$18)/E19 -> #DIV/0! | F20: =+(F18+$A$18)/F19 -> #DIV/0! | G20: =+(G18+$A$18)/G19 -> #DIV/0! | H20: =+(H18+$A$18)/H19 -> #DIV/0! | I20: =+(I18+$A$18)/I19 -> #DIV/0! | J20: =+(J18+$A$18)/J19 -> #DIV/0! | K20: =+(K18+$A$18)/K19 -> #DIV/0!
A21: 100 | B21: grade B FOB BRZ | C21: =+C20+($A$21/C19) -> #DIV/0! | D21: =+D20+($A$21/D19) -> #DIV/0! | E21: =+E20+($A$21/E19) -> #DIV/0! | F21: =+F20+($A$21/F19) -> #DIV/0! | G21: =+G20+($A$21/G19) -> #DIV/0! | H21: =+H20+($A$21/H19) -> #DIV/0! | I21: =+I20+($A$21/I19) -> #DIV/0! | J21: =+J20+($A$21/J19) -> #DIV/0! | K21: =+K20+($A$21/K19) -> #DIV/0!
A22: 1.12 | B22: anhydrous FOB BRZ | C22: =+C20*$A$22 -> #DIV/0! | D22: =+D20*$A$22 -> #DIV/0! | E22: =+E20*$A$22 -> #DIV/0! | F22: =+F20*$A$22 -> #DIV/0! | G22: =+G20*$A$22 -> #DIV/0! | H22: =+H20*$A$22 -> #DIV/0! | I22: =+I20*$A$22 -> #DIV/0! | J22: =+J20*$A$22 -> #DIV/0! | K22: =+K20*$A$22 -> #DIV/0!
B24: CIF China | C24: =+C22+$D$3 -> #DIV/0! | D24: =+D22+$D$3 -> #DIV/0! | E24: =+E22+$D$3 -> #DIV/0! | F24: =+F22+$D$3 -> #DIV/0! | G24: =+G22+$D$3 -> #DIV/0! | H24: =+H22+$D$3 -> #DIV/0! | I24: =+I22+$D$3 -> #DIV/0! | J24: =+J22+$D$3 -> #DIV/0! | K24: =+K22+$D$3 -> #DIV/0!
A25: 1.3 | B25: Import duty | C25: =+C24*$A$25 -> #DIV/0! | D25: =+D24*$A$25 -> #DIV/0! | E25: =+E24*$A$25 -> #DIV/0! | F25: =+F24*$A$25 -> #DIV/0! | G25: =+G24*$A$25 -> #DIV/0! | H25: =+H24*$A$25 -> #DIV/0! | I25: =+I24*$A$25 -> #DIV/0! | J25: =+J24*$A$25 -> #DIV/0! | K25: =+K24*$A$25 -> #DIV/0!
B27: CIF usd/mt | C27: =+C25/$A$4 -> #DIV/0! | D27: =+D25/$A$4 -> #DIV/0! | E27: =+E25/$A$4 -> #DIV/0! | F27: =+F25/$A$4 -> #DIV/0! | G27: =+G25/$A$4 -> #DIV/0! | H27: =+H25/$A$4 -> #DIV/0! | I27: =+I25/$A$4 -> #DIV/0! | J27: =+J25/$A$4 -> #DIV/0! | K27: =+K25/$A$4 -> #DIV/0!
B31: China domestic price

Sheet USA
C3: 264.172
B4: Arbitrage Brazil to California | H4: 3000
B5: Updated: | C5: 44286 | H5: =+H4/I5 -> #DIV/0! | I5: =+'settlement day'!H30 -> 0
B7: Volume | C7: 40000 | D7: m3 | E7: =(+C7*C3)/1000 -> 10566.88 | F7: mln gal | Q7: 2.4825
B8: FOB Santos | C8: 545 | D8: per m3 | E8: JUNE | F8: loading | I8: FREIGHT | Q8: 0.365
B9: FOB Santos | C9: =C8/264.172 -> 2.0630498 | D9: per gallon | I9: 05/02/2021: spi: $1.7-1.75 m as a guide | Q9: =+Q7+Q8 -> 2.8475
B10: Frt ($/mT) | C10: =E10/334 -> 0.16601777 | D10: per gallon | E10: =+I12 -> 55.449937 | F10: usd/mt | I10: 1750000 | J10: usd lps | K10: 400/400 | Q10: =+Q9*264.172 -> 752.22977
B11: CIF Cali | C11: =C9+C10 -> 2.2290676 | D11: per gallon | I11: =40000*0.789 -> 31560 | J11: mt | P11: FOB | Q11: =+Q10/1.1 -> 683.84525 | R11: eur/cbm
B12: CIF Cali ME importer of record | C12: =C11*1.025 -> 2.2847943 | D12: per gallon | E12: =+C12*C3 -> 603.57868 | F12: USD/cbm | I12: =+I10/I11 -> 55.449937 | J12: usd/mt
L13: =+I12*0.789 -> 43.75
B15: LCSF Baseline | C15: 79.9 | D15: CI value
B16: LCFS (Brazil) | C16: 58 | D16: CI value | I16: CIF SALE TO ME
B17: LCFS CI value | C17: =+'settlement day'!BJ34 -> 0 | D17: per gallon | I17: =+C9 -> 2.0630498 | J17: FOB Santos
B18: LCFS ( Brazilian producer) | C18: =(C15-C16)*C17 -> 0 | D18: per gallon | I18: 0.005 | J18: Costings
B19: D6 2021 | C19: =+'settlement day'!BG34 -> 0 | D19: per gallon | I19: =+C10 -> 0.16601777 | J19: Freight
B20: D5 2021 | C20: =+'settlement day'!BI34 -> 0 | D20: per gallon | I20: 0.01 | J20: Demurrage
B21: D5-D6 | C21: =C20-C19 -> 0 | D21: per gallon | I21: 0.01 | J21: MEG
B22: Total CI+RIN pick-up | C22: =(C21+C18)*E22 -> 0 | D22: per gallon | E22: 1 | I22: =SUM(I17:I21) -> 2.2540676 | J22: =+I22*C3 -> 595.46155 | K22: USD/cbm
B23: Total CI+RIN pick-up | C23: =C22*$C$3 -> 0 | D23: per m3
E24: OPIS spot | G24: Platts
B25: CIF Cali with Credit | C25: =C12-C22 -> 2.2847943 | E25: Argo | F25: =+'settlement day'!AY34 -> 0
B26: Cali delivered (CHIP + differential) | C26: =+F28+G27 -> 0.18 | E26: LA | F26: =+'settlement day'!AY38 -> 0 | H26: =+F25+G27 -> 0.18
F27: =+F26-F25 -> 0 | G27: 0.18
E28: CHIP | F28: =+'settlement day'!I9 -> 0 | G28: JULY | H28: arrival
B29: Bzl /Cali arb | C29: =C26-C25 -> -2.1047943 | D29: =+C29*C3 -> -556.02772 | F29: =+F28-C25 -> -2.2847943
B31: Duty Drawback (2.5%) | C31: =C11*0.025 -> 0.05572669 | D31: per gallon
B32: Duty Drawback (2.5%) | C32: =C31*264.172 -> 14.721431 | D32: per m3
B39: FLORIDA / USGC
B40: 0.12 | D40: usd/cbm
B41: LYB / Florida ind bid | D41: =(+'settlement day'!I9+B40)*C3 -> 31.70064 | F41: JULY arrival
B42: CIF USGC/USEC | C42: =+D41-D42 -> #REF! | D42: =+('FOB origin'!#REF!)+('Freight matrix'!H16*0.789) -> #REF! | E42: b3
C43: =+D41-D43 -> #REF! | D43: =+'FOB origin'!#REF!+('Freight matrix'!$H$16*0.789) -> #REF! | E43: phys

Sheet Freight matrix
B1: Last update | C1: April 21
B3: Freight rates in USD/MT
B4: ex USGC | C4: 5kt | E4: 10kt | G4: 20kt | I4: 30kt | K4: 40kt
B5: ARA | C5: 57 | D5: 60 | E5: 47 | F5: 55 | G5: 39 | H5: 42 | I5: 32 | J5: 35 | K5: 29 | L5: 32
B6: France | C6: 57 | D6: 60 | E6: 47 | F6: 55 | G6: 39 | H6: 42 | I6: 32 | J6: 35 | K6: 29 | L6: 32
B7: Baltics | C7: 57 | D7: 60 | E7: 47 | F7: 60 | G7: 39 | H7: 42 | I7: 32 | J7: 35 | K7: 29 | L7: 32
B8: North Brazil | C8: 65 | D8: 68 | E8: 55 | F8: 57 | G8: 40 | H8: 42 | I8: 37 | J8: 39 | K8: 30 | L8: 33
B9: Southeast Brazil | C9: - | D9: - | E9: - | F9: - | G9: 47 | H9: 49 | I9: 44 | J9: 46 | K9: 37 | L9: 40
B10: Colombia / Caribe | D10: 60 | F10: 50
B11: Far East | C11: 80 | D11: 83 | E11: 72 | F11: 75 | G11: 62 | H11: 65 | I11: 52 | J11: 55 | K11: 47 | L11: 50 | P11: 35
B12: WCI/AG | C12: 81 | D12: 85 | E12: 74 | F12: 78 | G12: 65 | H12: 70 | I12: 60 | J12: 65 | K12: 55 | L12: 60 | P12: =+P11*0.789 -> 27.615
B13: CHINA
B15: ex BRAZIL | C15: 5kt | E15: 10kt | G15: 20kt | I15: 30kt | K15: 40kt
B16: USG/USEC | C16: 50 | D16: 53 | E16: 43 | F16: 46 | G16: 32 | H16: 35 | I16: 26 | J16: 28 | K16: 22 | L16: 25
B17: USWC | C17: - | D17: - | E17: - | F17: - | G17: 70 | H17: 73 | I17: 53 | J17: 56 | K17: 39 | L17: 41
B18: ARA | C18: 65 | D18: 68 | E18: 50 | F18: 53 | G18: 40 | H18: 43 | I18: 32 | J18: 35 | K18: - | L18: -
B19: France | C19: 65 | D19: 68 | E19: 50 | F19: 53 | G19: 40 | H19: 43 | I19: 32 | J19: 35 | K19: - | L19: -
B20: Baltics | C20: 65 | D20: 68 | E20: 50 | F20: 53 | G20: 40 | H20: 43 | I20: 32 | J20: 35 | K20: - | L20: -
B21: Colombia / Caribe
B22: Far East | C22: 80 | D22: 83 | E22: 85 | F22: 90 | G22: 64 | H22: 68 | I22: 52 | J22: 55 | K22: 46 | L22: 49
B23: WCI/AG | C23: - | D23: - | E23: 70 | F23: 73 | G23: 53 | H23: 56 | I23: 55 | J23: 58 | K23: 48 | L23: 51
B24: CHINA | H24: 58 | J24: 55
B26: ex KARACHI | C26: 5kt | E26: 10kt | G26: 20kt | I26: 30kt | K26: 40kt
B27: ARA | C27: 85 | D27: 88 | E27: 73 | F27: 76 | G27: 65 | H27: 68 | I27: 55 | J27: 58 | K27: 45 | L27: 48
B28: FAR EAST | C28: 57 | D28: 60 | E28: 50 | F28: 53 | G28: 42 | H28: 45 | I28: 36 | J28: 39 | K28: 31 | L28: 33
B30: ex WCCAM/SAM | C30: 5kt | E30: 10kt | G30: 20kt | I30: 30kt | K30: 40kt
B31: North Brazil | C31: 71 | D31: 73 | E31: 60 | F31: 63 | G31: 49 | H31: 52 | I31: - | J31: - | K31: - | L31: -
B32: ARA | C32: 83 | D32: 86 | E32: 73 | F32: 76 | G32: 63 | H32: 66 | I32: 53 | J32: 56 | K32: 41 | L32: 45
B33: FAR EAST | C33: 85 | D33: 88 | E33: 75 | F33: 79 | G33: 67 | H33: 70 | I33: 59 | J33: 62 | K33: 50 | L33: 53

Sheet BRAZIL domestic
D2: BRAZILIAN DOMESTIC MARKET
I3: Date | J3: =+'settlement day'!B3 -> 45946
E4: Anhydrous premium over Hydrous | F4: =100%-(+E12/I12) -> 0.078169014 | I4: FX | J4: ='settlement day'!BA30 -> 5.7416
C6: EXPORTS | K6: IMPORTS
E7: BRL/cbm | F7: USD/cbm | H7: CS | I7: BRL/cbm | J7: USD/cbm | L7: NE | M7: BRL/cbm | N7: USD/cbm | O7: =470/0.867 -> 542.09919 | P7: 470 s/ICMS | Q7: 190 | R7: RS | S7: BRL/cbm | T7: USD/cbm
D8: HYDROUS | E8: =+'settlement day'!AY45 -> 0 | H8: ANHYDROUS | I8: =+'settlement day'!AY44 -> 0 | L8: ANHYDROUS | M8: =+'PLATTS&OPIS'!I256 -> 3900 | Q8: https://covid19.apple.com/mobility | R8: ANHYDROUS | S8: =+I8+Q7 -> 190
D9: (-) INSS 2,85% | E9: =+E8*2.85% -> 0 | I9: =+I8*2.85% -> 0 | M9: 0 | O9: (-) INSS 2,85% | S9: 0
D10: (-) ICMS 12% | E10: =+E8*12% -> 0 | I10: 122 | O10: (-) ICMS XX%
B11: 130.9 | D11: (-) PIS/COFINS | E11: 130.9 | I11: 20 | L11: 131 | M11: 0 | O11: (-) PIS/COFINS | S11: 149
E12: =+E8-(E9+E10+E11) -> -130.9 | I12: =+I8-(I9+I10+I11) -> -142 | J12: =+I12/E12 -> 1.0847976 | M12: =+M8-(M9+M10+M11) -> 3900 | S12: =+S8-(S9+S10+S11) -> 41
C13: 1 | D13: (+) CBIOS | E13: =+'settlement day'!BK34*'BRAZIL domestic'!C13 -> 41.25 | G13: 1.2 | I13: =+'settlement day'!BK34*'BRAZIL domestic'!G13 -> 49.5
D15: (+) Inland freight to port | E15: =+'mkt data'!G5 -> 300 | I15: =+E15 -> 300 | M15: 50 | O15: (+) Inland freight to hub | S15: 0
D16: (+) Terminal port | E16: =+'mkt data'!H8 -> 100 | I16: =+E16 -> 100 | M16: 0 | S16: 0
D18: (=) TOTAL | E18: =+E12+E13+E15+E16 -> 310.35 | F18: =+E18/$J$4 -> 54.052877 | I18: =+I12+I13+I15+I16 -> 307.5 | J18: =+I18/$J$4 -> 53.5565 | M18: =+M12+M15+M16 -> 3950 | N18: =+M18/$J$4 -> 687.96154 | S18: =+S12+S15+S16 -> 41 | T18: =+S18/$J$4 -> 7.1408667
D20: (+) Port costs | E20: 10 | F20: =+E20/J4 -> 1.7416748 | J20: =+F20 -> 1.7416748 | M20: 70 | N20: =+M20/$J$4 -> 12.191724 | O20: (+) Port costs | S20: 65 | T20: =+S20/$J$4 -> 11.320886
D21: (+) Inspection | E21: 5 | F21: =+E21/J4 -> 0.8708374 | J21: =+F21 -> 0.8708374 | M21: 15 | N21: =+M21/$J$4 -> 2.6125122 | O21: (+) Inspection | S21: 36 | T21: =+S21/$J$4 -> 6.2700293
D22: (+) EXPORT premium B grade | E22: =+'mkt data'!G4 -> 150 | F22: =+E22/J4 -> 26.125122 | J22: 0 | M22: 25 | N22: =+M22/$J$4 -> 4.354187 | O22: (+) Inland freight to hub | S22: 65 | T22: =+S22/$J$4 -> 11.320886
K23: 44593 | M23: =+N23*J4 -> 5.7416 | N23: 1 | O23: (+) other costs | S23: 10 | T23: =+S23/J4 -> 1.7416748
E24: FOB Santos | F24: =+F18+F20+F21+F22 -> 82.790511 | I24: FOB Santos | J24: =+J18+J20+J21+J22 -> 56.169012 | K24: 765 | M24: =+N24*J4 -> 516.09807 | N24: =+K24*K25 -> 89.8875 | O24: (+) PIS/COFINS on CFR | R24: =(+'settlement day'!M9+0.33+0.03)*264.172 -> 95.10192 | S24: =+T24*J4 -> 64.159369 | T24: =+R24*R25 -> 11.174476
K25: 0.1175 | M25: 100 | N25: =+M25/$J$4 -> 17.416748 | O25: (+) margin | R25: 0.1175 | S25: 100 | T25: =+S25/$J$4 -> 17.416748
M26: =SUM(M20:M25) -> 731.83967
N27: =+N18-(N20+N21+N22+N23+N24+N25) -> 560.49887 | O27: Suape Value with TRQ | T27: =+T18-(T20+T21+T22+T23+T24+T25) -> -52.103833
N28: =+N18-(N20+N21+N22+N23+N24+N25)-N29 -> 560.49887 | O28: Suape Value w/o TRQ | T28: =+T18-(T20+T21+T22+T23+T24+T25)-T29 -> -71.124217
K29: 0 | M29: =+N29*J4 -> 0 | N29: =+K29*K24 -> 0 | O29: Import duty | Q29: 0.2 | S29: =+T29*J4 -> 109.20744 | T29: =+Q29*R24 -> 19.020384
C32: BRAZILIAN DOMESTIC MARKET -- basis B3
E34: Frete | F34: 65 | G34: R$/cbm | H34: 65 | I34: 75 frete 14/6/21
E35: PIS/COFINS | F35: 130.9 | G35: R$/cbm
D36: 30 | E36: ICMS | F36: 0.133 | G36: 0.867
E37: anh/hydrous | F37: 0.14 | G37: 1.14
U39: 264.172
D40: 44621 | E40: 44652 | F40: 44682 | G40: 44713 | H40: 44743 | I40: 44774 | J40: 44805 | K40: 44835 | L40: 44866 | M40: 44896 | N40: 44927 | O40: 44958 | P40: 44986 | S40: 750
C41: B3 | D41: =+'settlement day'!Q13 -> 0 | E41: =+'settlement day'!R13 -> 0 | F41: =+'settlement day'!S13 -> 0 | G41: =+'settlement day'!T13 -> 0 | H41: =+'settlement day'!U13 -> 0 | I41: =+'settlement day'!V13 -> 0 | J41: =+'settlement day'!W13 -> 0 | K41: =+'settlement day'!X13 -> 0 | ... P41: =+'settlement day'!AC13 -> 0 | S41: =+S40/U39 -> 2.8390594
C42: ESALQ P | D42: =+'settlement day'!BI42 -> 2856.5
D43: =+D41-D42 -> -2856.5
C45: Ex plant | D45: =+(D41-$F$34+$F$35)/$G$36 -> 76.009227 | E45: =+(E41-$F$34+$F$35)/$G$36 -> 76.009227 | F45: =+(F41-$F$34+$F$35)/$G$36 -> 76.009227 | G45: =+(G41-$F$34+$F$35)/$G$36 -> 76.009227 | H45: =+(H41-$F$34+$F$35)/$G$36 -> 76.009227 | I45: =+(I41-$F$34+$F$35)/$G$36 -> 76.009227 | J45: =+(J41-$F$34+$F$35)/$G$36 -> 76.009227 | K45: =+(K41-$F$34+$F$35)/$G$36 -> 76.009227 | ... P45: =+(P41-$F$34+$F$35)/$G$36 -> 76.009227
C46: net tax | D46: =D41-$F$34 -> -65
C47: Anhydrous ex mill equivalent | D47: =((D41-$F$34)*$G$37)+$F$35 -> 56.8 | E47: =((E41-$F$34)*$G$37)+$F$35 -> 56.8 | F47: =((F41-$F$34)*$G$37)+$F$35 -> 56.8 | G47: =((G41-$F$34)*$G$37)+$F$35 -> 56.8 | H47: =((H41-$F$34)*$G$37)+$F$35 -> 56.8 | I47: =((I41-$F$34)*$G$37)+$F$35 -> 56.8 | J47: =((J41-$F$34)*$G$37)+$F$35 -> 56.8 | K47: =((K41-$F$34)*$G$37)+$F$35 -> 56.8 | ... P47: =((P41-$F$34)*$G$37)+$F$35 -> 56.8
C49: ESALQ RB | D49: =+'settlement day'!$BI$43 -> 0
D50: =+D46-D49 -> -65
D52: =+((D49+$F$35)/$G$36)+H34 -> 215.98039

Sheet INDIA
A1: ='settlement day'!B3 -> 45946 | B1: INDIA
B2: ST ROSE | C2: Freight | D2: =F2/$A$5 -> 0 | E2: usd/cbm | G2: pmt
B3: GALVESTON | C3: Freight | D3: =F3/$A$5 -> 82.382763 | E3: usd/cbm | F3: 65 | G3: pmt
A4: 264.172 | B4: SANTOS | C4: Freight | D4: =F4/$A$5 -> 0 | E4: usd/cbm | G4: pmt
A5: 0.789 | C5: Volume | D5: 20000 | E5: cbm | F5: =D5*A5 -> 15780 | G5: mt
A7: 0.18 | B7: cpg
A8: Basis | B8: US | C8: 45992 | D8: 46023 | E8: 46054 | F8: 46082 | G8: 46113 | H8: 46143 | I8: 46174 | J8: 46204 | K8: 46235 | L8: 46266 | M8: 46296 | N8: 46327 | O8: 46357
B9: CHIP | C9: ='settlement day'!BJ9 -> 1.63 | D9: ='settlement day'!BK9 -> 1.5775 | E9: ='settlement day'!BL9 -> 1.5825 | F9: ='settlement day'!BM9 -> 1.6075 | G9: ='settlement day'!BN9 -> 1.6325 | H9: ='settlement day'!BO9 -> 1.655 | I9: ='settlement day'!BP9 -> 1.6675 | J9: ='settlement day'!BQ9 -> 1.6725 | ... O9: ='settlement day'!BV9 -> 1.5825
B11: FOB US usd/cbm | C11: =+(C9+$A$7)*$A$4 -> 478.15132 | D11: =+(D9+$A$7)*$A$4 -> 464.28229 | E11: =+(E9+$A$7)*$A$4 -> 465.60315 | F11: =+(F9+$A$7)*$A$4 -> 472.20745 | G11: =+(G9+$A$7)*$A$4 -> 478.81175 | H11: =+(H9+$A$7)*$A$4 -> 484.75562 | I11: =+(I9+$A$7)*$A$4 -> 488.05777 | J11: =+(J9+$A$7)*$A$4 -> 489.37863 | ... O11: =+(O9+$A$7)*$A$4 -> 465.60315
B13: CIF INDIA usd/cbm | C13: =+C11+$D$2 -> 478.15132 | D13: =+D11+$D$2 -> 464.28229 | E13: =+E11+$D$2 -> 465.60315 | F13: =+F11+$D$2 -> 472.20745 | G13: =+G11+$D$2 -> 478.81175 | H13: =+H11+$D$2 -> 484.75562 | I13: =+I11+$D$2 -> 488.05777 | J13: =+J11+$D$2 -> 489.37863 | ... O13: =+O11+$D$2 -> 465.60315
B14: Anhydrous CIF INDIA usd/mt | C14: =+C13/$A$5 -> 606.02195 | D14: =+D13/$A$5 -> 588.44397 | E14: =+E13/$A$5 -> 590.11806 | F14: =+F13/$A$5 -> 598.48853 | G14: =+G13/$A$5 -> 606.859 | H14: =+H13/$A$5 -> 614.39242 | I14: =+I13/$A$5 -> 618.57766 | J14: =+J13/$A$5 -> 620.25175 | ... O14: =+O13/$A$5 -> 590.11806
A17: inland
A18: =+'mkt data'!G6+'mkt data'!G8 -> 90 | B18: BRAZIL | C18: 45992 | D18: 46023 | E18: 46054 | F18: 46082 | G18: 46113 | H18: 46143 | I18: 46174 | J18: 46204 | K18: 46235 | L18: 46266 | M18: 46296 | N18: 46327 | O18: 46357
A19: brl/cbm | B19: B3 | C19: ='settlement day'!BJ13 -> 2904.5 | D19: ='settlement day'!BK13 -> 2930 | E19: ='settlement day'!BL13 -> 2950 | F19: ='settlement day'!BM13 -> 2975 | G19: ='settlement day'!BN13 -> 2700 | H19: ='settlement day'!BO13 -> 2420 | I19: ='settlement day'!BP13 -> 2390 | J19: ='settlement day'!BQ13 -> 2485 | ... O19: ='settlement day'!BV13 -> 2605
B20: BRL/USD | C20: ='settlement day'!BJ30 -> 5.5005501 | D20: ='settlement day'!BK30 -> 5.538632 | E20: ='settlement day'!BL30 -> 5.574136 | F20: ='settlement day'!BM30 -> 5.6132473 | G20: ='settlement day'!BN30 -> 5.6561086 | H20: ='settlement day'!BO30 -> 5.6963828 | I20: ='settlement day'!BP30 -> 5.7355893 | J20: ='settlement day'!BQ30 -> 5.7786767 | ... O20: ='settlement day'!BV30 -> 5.9772863
B22: hydrous FOB BRZ | C22: ='FOB origin'!BF20 -> 553.27324 | D22: ='FOB origin'!BG20 -> 554.13414 | E22: ='FOB origin'!BH20 -> 554.24914 | F22: ='FOB origin'!BI20 -> 554.90289 | G22: ='FOB origin'!BJ20 -> 502.14514 | H22: ='FOB origin'!BK20 -> 449.50364 | I22: ='FOB origin'!BL20 -> 441.26114 | J22: ='FOB origin'!BM20 -> 454.47689 | ... O22: ='FOB origin'!BR20 -> 459.74664
A23: 100 | B23: grade B FOB BRZ | C23: ='FOB origin'!BF21 -> 636.90124 | D23: ='FOB origin'!BG21 -> 637.18714 | E23: ='FOB origin'!BH21 -> 636.77314 | F23: ='FOB origin'!BI21 -> 636.85189 | G23: ='FOB origin'!BJ21 -> 583.47314 | H23: ='FOB origin'!BK21 -> 530.25664 | I23: ='FOB origin'!BL21 -> 521.46214 | J23: ='FOB origin'!BM21 -> 534.07989 | ... O23: ='FOB origin'!BR21 -> 536.70464
A24: 1.125 | B24: anhydrous FOB BRZ | C24: ='FOB origin'!BF22 -> 622.50922 | D24: ='FOB origin'!BG22 -> 623.47773 | E24: ='FOB origin'!BH22 -> 623.60711 | F24: ='FOB origin'!BI22 -> 624.34257 | G24: ='FOB origin'!BJ22 -> 564.99011 | H24: ='FOB origin'!BK22 -> 505.76842 | I24: ='FOB origin'!BL22 -> 496.49561 | J24: ='FOB origin'!BM22 -> 511.36332 | ... O24: ='FOB origin'!BR22 -> 517.29179
B26: CIF INDIA usd/cbm | C26: =+C22+$D$4 -> 553.27324 | D26: =+D22+$D$4 -> 554.13414 | E26: =+E22+$D$4 -> 554.24914 | F26: =+F22+$D$4 -> 554.90289 | G26: =+G22+$D$4 -> 502.14514 | H26: =+H22+$D$4 -> 449.50364 | I26: =+I22+$D$4 -> 441.26114 | J26: =+J22+$D$4 -> 454.47689 | ... O26: =+O22+$D$4 -> 459.74664
B27: hydrous CIF INDIA usd/mt | C27: =+C26/$A$5 -> 701.23352 | D27: =+D26/$A$5 -> 702.32464 | E27: =+E26/$A$5 -> 702.4704 | F27: =+F26/$A$5 -> 703.29898 | G27: =+G26/$A$5 -> 636.43238 | H27: =+H26/$A$5 -> 569.71311 | I27: =+I26/$A$5 -> 559.26634 | J27: =+J26/$A$5 -> 576.01634 | ... O27: =+O26/$A$5 -> 582.69537
A29: 1.07 | B29: water discount
B30: hydrous net back value compared to anhydrous US | C30: =C11/$A$29 -> 446.87039 | D30: =D11/$A$29 -> 433.90868 | E30: =E11/$A$29 -> 435.14313 | F30: =F11/$A$29 -> 441.31537 | G30: =G11/$A$29 -> 447.48762 | H30: =H11/$A$29 -> 453.04264 | I30: =I11/$A$29 -> 456.12876 | J30: =J11/$A$29 -> 457.36321 | ... O30: =O11/$A$29 -> 435.14313
B31: diff Brazilian FOB vs US | C31: =C22-C30 -> 106.40285 | D31: =D22-D30 -> 120.22546 | E31: =E22-E30 -> 119.10601 | F31: =F22-F30 -> 113.58752 | G31: =G22-G30 -> 54.657528 | H31: =H22-H30 -> -3.5389907 | I31: =I22-I30 -> -14.867612 | J31: =J22-J30 -> -2.8863108 | ... O31: =O22-O30 -> 24.603514
B34: CIF vs CIF pmt | C34: =C27-C14 -> 95.211565 | D34: =D27-D14 -> 113.88068 | E34: =E27-E14 -> 112.35234 | F34: =F27-F14 -> 104.81045 | G34: =G27-G14 -> 29.573377 | H34: =H27-H14 -> -44.679309 | I34: =I27-I14 -> -59.311312 | J34: =J27-J14 -> -44.235406 | ... O34: =O27-O14 -> -7.4226935
A39: 100 | B39: bid premium pmt
A40: 9 | B40: costs
B41: India indicative bid anhydrous
B42: CIF India usd/mt | C42: =((C9*$A$4)/$A$5)+$A$39 -> 645.75458 | D42: =((D9*$A$4)/$A$5)+$A$39 -> 628.17659 | E42: =((E9*$A$4)/$A$5)+$A$39 -> 629.85068 | F42: =((F9*$A$4)/$A$5)+$A$39 -> 638.22115 | G42: =((G9*$A$4)/$A$5)+$A$39 -> 646.59162 | H42: =((H9*$A$4)/$A$5)+$A$39 -> 654.12504 | I42: =((I9*$A$4)/$A$5)+$A$39 -> 658.31028 | J42: =((J9*$A$4)/$A$5)+$A$39 -> 659.98437 | ... O42: =((O9*$A$4)/$A$5)+$A$39 -> 629.85068
B43: FOB US usd/mt | C43: =C42+$A$40+$F$3 -> 719.75458 | D43: =D42+$A$40+$F$3 -> 702.17659 | E43: =E42+$A$40+$F$3 -> 703.85068 | F43: =F42+$A$40+$F$3 -> 712.22115 | G43: =G42+$A$40+$F$3 -> 720.59162 | H43: =H42+$A$40+$F$3 -> 728.12504 | I43: =I42+$A$40+$F$3 -> 732.31028 | J43: =J42+$A$40+$F$3 -> 733.98437 | ... O43: =O42+$A$40+$F$3 -> 703.85068
B44: FOB US usd/cbm | C44: =C43*$A$5 -> 567.88636 | D44: =D43*$A$5 -> 554.01733 | E44: =E43*$A$5 -> 555.33819 | F44: =F43*$A$5 -> 561.94249 | G44: =G43*$A$5 -> 568.54679 | H44: =H43*$A$5 -> 574.49066 | I44: =I43*$A$5 -> 577.79281 | J44: =J43*$A$5 -> 579.11367 | ... O44: =O43*$A$5 -> 555.33819
B45: FOB US cpg CHIP | C45: =(C44/$A$4)-C9 -> 0.51968415 | D45: =(D44/$A$4)-D9 -> 0.51968415 | E45: =(E44/$A$4)-E9 -> 0.51968415 | F45: =(F44/$A$4)-F9 -> 0.51968415 | G45: =(G44/$A$4)-G9 -> 0.51968415 | H45: =(H44/$A$4)-H9 -> 0.51968415 | I45: =(I44/$A$4)-I9 -> 0.51968415 | J45: =(J44/$A$4)-J9 -> 0.51968415 | ... O45: =(O44/$A$4)-O9 -> 0.51968415
A47: 1.07 | B47: water discount
B48: India indicative bid hydrous
B49: FOB BRZ usd/cbm | C49: =C44/$A$47 -> 530.73492 | D49: =D44/$A$47 -> 517.77321 | E49: =E44/$A$47 -> 519.00765 | F49: =F44/$A$47 -> 525.1799 | G49: =G44/$A$47 -> 531.35214 | H49: =H44/$A$47 -> 536.90716 | I49: =I44/$A$47 -> 539.99328 | J49: =J44/$A$47 -> 541.22773 | ... O49: =O44/$A$47 -> 519.00765
C59: 0.789
C60: 264.172 | E60: june | I60: Raizen 22/4/21 -- FX 5.44
C61: chip cbm | D61: =+E61*C60 -> 418.05219 | E61: =+E9 -> 1.5825 | I61: 629 | J61: usd/cbm FOB
C62: chip pmt | D62: =+D61/C59 -> 529.85068 | I62: =+I61/A5 -> 797.21166 | J62: usd/mt FOB
C63: bid premium pmt | D63: 100 | I63: =+I62+45 -> 842.21166 | J63: usd/mt CIF
C64: bid CIF WCI | D64: =+D62+D63 -> 629.85068 | E64: pmt
...

Sheet FOB origin
C1: FOB ORIGIN
B2: 264.172
B3: 0.789
B4: 0.1 | AH4: =+(AH9+$B$4)*$B$2 -> 26.4172 | AI4: =+(AI9+$B$4)*$B$2 -> 26.4172 | AJ4: =+(AJ9+$B$4)*$B$2 -> 26.4172 | AK4: =+(AK9+$B$4)*$B$2 -> 26.4172 | AL4: =+(AL9+$B$4)*$B$2 -> 26.4172 | AM4: =+(AM9+$B$4)*$B$2 -> 26.4172 | AN4: =+(AN9+$B$4)*$B$2 -> 26.4172 | AO4: =+(AO9+$B$4)*$B$2 -> 26.4172 | ... BR4: =+(BR9+$B$4)*$B$2 -> 444.46939
C6: FOB ORIGIN | D6: 44317 | E6: 44378 | F6: 44409 | G6: 44440 | H6: 44470 | I6: 44501 | J6: 44531 | K6: 44562 | L6: 44593 | M6: 44621 | N6: 44652 | O6: 44682 | P6: 44713 | Q6: 44743 | R6: 44774 | S6: 44805 | T6: 44835 | U6: 44866 | V6: 44896 | W6: 44927 | X6: 44958 | Y6: 44986 | Z6: 45017 | AA6: 45047 | AB6: 45078 | AC6: 45108 | AD6: 45139 | AE6: 45170 | AF6: 45200 | AG6: 45231 | AH6: 45261 | AI6: 45292 | AJ6: 45323 | AK6: 45352 | AL6: 45383 | AM6: 45413 | AN6: 45444 | AO6: 45474 | AP6: 45505 | AQ6: 45536 | AR6: 45566 | AS6: 45597 | AT6: 45627 | AU6: 45658 | AV6: 45689 | AW6: 45717 | AX6: 45748 | AY6: 45778 | AZ6: 45809 | BA6: 45839 | BB6: 45870 | BC6: 45901 | BD6: 45931 | BE6: 45962 | BF6: 45992 | BG6: 46023 | BH6: 46054 | BI6: 46082 | BJ6: 46113 | BK6: 46143 | BL6: 46174 | BM6: 46204 | BN6: 46235 | BO6: 46266 | BP6: 46296 | BQ6: 46327 | BR6: 46357 | BT6: Cbios | BU6: CBio unit | BV6: per vol HYD | BW6: per vol ANH
C7: USGC | BT7: R$ | BU7: =+'settlement day'!BO42 -> 41.25 | BV7: =+'settlement day'!BP42 -> 44.212219 | BW7: =+'settlement day'!BQ42 -> 50.121507
C8: D-1 | D8: =+'settlement day'!G11 -> 0 | E8: =+'settlement day'!I11 -> 0 | F8: =+'settlement day'!J11 -> 0 | G8: =+'settlement day'!K11 -> 0 | H8: =+'settlement day'!L11 -> 0 | I8: =+'settlement day'!M11 -> 0 | J8: =+'settlement day'!N11 -> 0 | K8: =+'settlement day'!O11 -> 0 | L8: =+'settlement day'!P11 -> 0 | ... BR8: =+'settlement day'!BV11 -> 0 | BT8: U$ | BU8: =+'settlement day'!BO43 -> 8.2786441 | BV8: =+'settlement day'!BP43 -> 8.8731448 | BW8: =+'settlement day'!BQ43 -> 10.059106
C9: CHIP | D9: =+'settlement day'!G9 -> 0 | E9: =+'settlement day'!I9 -> 0 | F9: =+'settlement day'!J9 -> 0 | G9: =+'settlement day'!K9 -> 0 | H9: =+'settlement day'!L9 -> 0 | I9: =+'settlement day'!M9 -> 0 | J9: =+'settlement day'!N9 -> 0 | K9: =+'settlement day'!O9 -> 0 | L9: =+'settlement day'!P9 -> 0 | ... BR9: =+'settlement day'!BV9 -> 1.5825 | BV9: =+BW8-BV8 -> 1.185961
B11: 0.1 | C11: FOB US IMTT - D12 | D11: =+(D9+$B$11)*$B$2 -> 26.4172 | E11: =+(E9+$B$11)*$B$2 -> 26.4172 | F11: =+(F9+$B$11)*$B$2 -> 26.4172 | G11: =+(G9+$B$11)*$B$2 -> 26.4172 | H11: =+(H9+$B$11)*$B$2 -> 26.4172 | I11: =+(I9+$B$11)*$B$2 -> 26.4172 | J11: =+(J9+$B$11)*$B$2 -> 26.4172 | K11: =+(K9+$B$11)*$B$2 -> 26.4172 | ... BR11: =+(BR9+$B$11)*$B$2 -> 444.46939
A12: 0.08 | B12: =+'mkt data'!G14 -> 0.27 | C12: FOB US IMTT - U3 | D12: =+(D9+$B$12)*$B$2 -> 71.32644 | E12: =+(E9+$B$12)*$B$2 -> 71.32644 | F12: =+(F9+$B$12)*$B$2 -> 71.32644 | G12: =+(G9+$B$12)*$B$2 -> 71.32644 | H12: =+(H9+$B$12)*$B$2 -> 71.32644 | I12: =+(I9+$B$12)*$B$2 -> 71.32644 | J12: =+(J9+$B$12)*$B$2 -> 71.32644 | K12: =+(K9+$B$12)*$B$2 -> 71.32644 | ... BF12: =+(BF9+$B$12)*$B$2 -> 501.9268 | BG12: =+(BG9+$B$12+$A$12)*$B$2 -> 509.19153 | BH12: =+(BH9+$B$12+$A$12)*$B$2 -> 510.51239 | BI12: =+(BI9+$B$12+$A$12)*$B$2 -> 517.11669 | BJ12: =+(BJ9+$B$12+$A$12)*$B$2 -> 523.72099 | BK12: =+(BK9+$B$12+$A$12)*$B$2 -> 529.66486 | BL12: =+(BL9+$B$12+$A$12)*$B$2 -> 532.96701 | BM12: =+(BM9+$B$12+$A$12)*$B$2 -> 534.28787 | BN12: =+(BN9+$B$12+$A$12)*$B$2 -> 532.96701 | ... BR12: =+(BR9+$B$12+$A$12)*$B$2 -> 510.51239
C14: BRAZIL CS
B15: inland | C15: D-1 | D15: =+'settlement day'!G15 -> 0 | E15: =+'settlement day'!I15 -> 0 | F15: =+'settlement day'!J15 -> 0 | G15: =+'settlement day'!K15 -> 0 | H15: =+'settlement day'!L15 -> 0 | I15: =+'settlement day'!M15 -> 0 | J15: =+'settlement day'!N15 -> 0 | K15: =+'settlement day'!O15 -> 0 | L15: =+'settlement day'!P15 -> 0 | ... BR15: =+'settlement day'!BV15 -> 0
B16: =+'mkt data'!G23 -> 90 | C16: B3 ETH Brazil | D16: =+'settlement day'!G13 -> 0 | E16: =+'settlement day'!I13 -> 0 | F16: =+'settlement day'!J13 -> 0 | G16: =+'settlement day'!K13 -> 0 | H16: =+'settlement day'!L13 -> 0 | I16: =+'settlement day'!M13 -> 0 | J16: =+'settlement day'!N13 -> 0 | K16: =+'settlement day'!O13 -> 0 | L16: =+'settlement day'!P13 -> 0 | ... BR16: =+'settlement day'!BV13 -> 2605
B17: brl/cbm | C17: BRL/USD | D17: =+'settlement day'!G30 -> 0 | E17: =+'settlement day'!I30 -> 0 | F17: =+'settlement day'!J30 -> 0 | G17: =+'settlement day'!K30 -> 0 | H17: =+'settlement day'!L30 -> 0 | I17: =+'settlement day'!M30 -> 0 | J17: =+'settlement day'!N30 -> 0 | K17: =+'settlement day'!O30 -> 0 | L17: =+'settlement day'!P30 -> 0 | ... BR17: =+'settlement day'!BV30 -> 5.9772863 | BT17: ADD CBIO VALUE , factor for HYDROUS and ANHYDROUS
BV18: HYD | BW18: ANH
B20: =+(B31+B32)-B16 -> 460 | C20: Hydrous FOB BRZ | D20: =+(D16+$B$16)/D17 -> #DIV/0! | E20: =+(E16+$B$16)/E17 -> #DIV/0! | F20: =+(F16+$B$16)/F17 -> #DIV/0! | G20: =+(G16+$B$16)/G17 -> #DIV/0! | H20: =+(H16+$B$16)/H17 -> #DIV/0! | I20: =+(I16+$B$16)/I17 -> #DIV/0! | J20: =+(J16+$B$16)/J17 -> #DIV/0! | K20: =+(K16+$B$16)/K17 -> #DIV/0! | L20: =+((L16+$B$16)/L17)+BV8 -> #DIV/0! | M20: =+((M16+$B$16)/M17)+$BV$8 -> #DIV/0! | N20: =+((N16+$B$16)/N17)+$BV$8 -> #DIV/0! | O20: =+((O16+$B$16)/O17)+$BV$8 -> #DIV/0! | P20: =+((P16+$B$16)/P17)+$BV$8 -> #DIV/0! | Q20: =+((Q16+$B$16)/Q17)+$BV$8 -> #DIV/0! | R20: =+((R16+$B$16)/R17)+$BV$8 -> #DIV/0! | S20: =+((S16+$B$16)/S17)+$BV$8 -> #DIV/0! | T20: =+((T16+$B$16)/T17)+$BV$8 -> #DIV/0! | ... BR20: =+((BR16+$B$16)/BR17)+$BV$8 -> 459.74664 | BU20: cbio $/cbm | BV20: 23.533119 | BW20: 24.609798
B21: =+'mkt data'!H2 -> 1.125 | C21: Grade B FOB BRZ | D21: =+D20+($B$20/D17) -> #DIV/0! | E21: =+E20+($B$20/E17) -> #DIV/0! | F21: =+F20+($B$20/F17) -> #DIV/0! | G21: =+G20+($B$20/G17) -> #DIV/0! | H21: =+H20+($B$20/H17) -> #DIV/0! | I21: =+I20+($B$20/I17) -> #DIV/0! | J21: =+J20+($B$20/J17) -> #DIV/0! | K21: =+K20+($B$20/K17) -> #DIV/0! | ... BR21: =+BR20+($B$20/BR17) -> 536.70464
B22: =+EU!BG3 -> 0 | C22: Anhydrous FOB BRZ | D22: =+D20*$B$21 -> #DIV/0! | E22: =+E20*$B$21 -> #DIV/0! | F22: =+F20*$B$21 -> #DIV/0! | G22: =+G20*$B$21 -> #DIV/0! | H22: =+H20*$B$21+$B$22 -> #DIV/0! | I22: =+I20*$B$21+$B$22 -> #DIV/0! | J22: =+J20*$B$21+$B$22 -> #DIV/0! | K22: =+K20*$B$21+$B$22 -> #DIV/0! | L22: =+L20*$B$21+$B$22+$BW$8 -> #DIV/0! | M22: =+M20*$B$21+$B$22+$BW$8 -> #DIV/0! | N22: =+N20*$B$21+$B$22+$BW$8 -> #DIV/0! | O22: =+O20*$B$21+$B$22+$BW$8 -> #DIV/0! | P22: =+P20*$B$21+$B$22+$BW$8 -> #DIV/0! | Q22: =+Q20*$B$21+$B$22+$BW$8 -> #DIV/0! | R22: =+R20*$B$21+$B$22+$BW$8 -> #DIV/0! | S22: =+S20*$B$21+$B$22+$BW$8 -> #DIV/0! | ... W22: =+W20*$B$21+$B$22+$BW$8 -> #DIV/0! | X22: =+(X20-$BV$8)*$B$21+$B$22+$BW$8 -> #DIV/0! | Y22: =+(Y20-$BV$8)*$B$21+$B$22+$BW$8 -> #DIV/0! | Z22: =+(Z20-$BV$8)*$B$21+$B$22+$BW$8 -> #DIV/0! | AA22: =+(AA20-$BV$8)*$B$21+$B$22+$BW$8 -> #DIV/0! | AB22: =+(AB20-$BV$8)*$B$21+$B$22+$BW$8 -> #DIV/0! | AC22: =+(AC20-$BV$8)*$B$21+$B$22+$BW$8 -> #DIV/0! | AD22: =+(AD20-$BV$8)*$B$21+$B$22+$BW$8 -> #DIV/0! | AE22: =+(AE20-$BV$8)*$B$21+$B$22+$BW$8 -> #DIV/0! | ... BR22: =+(BR20-$BV$8)*$B$21+$B$22+$BW$8 -> 517.29179 | BY22: 520
C23: hyd CHIP basis net back cpg | AI23: =+((AI20/264.172)-AI9)*100 -> 10.23739 | AJ23: =+((AJ20/264.172)-AJ9)*100 -> 10.196251 | AK23: =+((AK20/264.172)-AK9)*100 -> 10.178595 | AL23: =+((AL20/264.172)-AL9)*100 -> 9.9470152 | AM23: =+((AM20/264.172)-AM9)*100 -> 9.8592736 | AN23: =+((AN20/264.172)-AN9)*100 -> 9.4881918 | AO23: =+((AO20/264.172)-AO9)*100 -> 9.3764638 | AP23: =+((AP20/264.172)-AP9)*100 -> 9.3827415 | ... BR23: =+((BR20/264.172)-BR9)*100 -> 15.783071 | BY23: =40*0.789 -> 31.56
B24: 1 | C24: Anhydrous FOB- flat hyd | D24: =+D22*$B$21 -> #DIV/0! | E24: =+E22*$B$21 -> #DIV/0! | F24: =+F22*$B$21 -> #DIV/0! | G24: =+G22*$B$21 -> #DIV/0! | H24: =+H22*$B$21+$B$22 -> #DIV/0! | I24: =+I22*$B$21+$B$22 -> #DIV/0! | J24: =+J22*$B$21+$B$22 -> #DIV/0! | K24: =+K22*$B$21+$B$22 -> #DIV/0! | L24: =+L22*$B$21+$B$22+$BW$8 -> #DIV/0! | M24: =+M22*$B$21+$B$22+$BW$8 -> #DIV/0! | N24: =+N22*$B$21+$B$22+$BW$8 -> #DIV/0! | O24: =+O22*$B$21+$B$22+$BW$8 -> #DIV/0! | P24: =+P22*$B$21+$B$22+$BW$8 -> #DIV/0! | Q24: =+Q22*$B$21+$B$22+$BW$8 -> #DIV/0! | R24: =+R22*$B$21+$B$22+$BW$8 -> #DIV/0! | S24: =+S22*$B$21+$B$22+$BW$8 -> #DIV/0! | ... W24: =+W22*$B$21+$B$22+$BW$8 -> #DIV/0! | X24: =+(X22-$BV$8)*$B$21+$B$22+$BW$8 -> #DIV/0! | Y24: =+(Y22-$BV$8)*$B$21+$B$22+$BW$8 -> #DIV/0! | Z24: =+(Z22-$BV$8)*$B$21+$B$22+$BW$8 -> #DIV/0! | AA24: =+(AA22-$BV$8)*$B$21+$B$22+$BW$8 -> #DIV/0! | AB24: =+(AB22-$BV$8)*$B$21+$B$22+$BW$8 -> #DIV/0! | AC24: =+(AC22-$BV$8)*$B$21+$B$22+$BW$8 -> #DIV/0! | AD24: =+(AD22-$BV$8)*$B$21+$B$22+$BW$8 -> #DIV/0! | AE24: =+(AE22-$BV$8)*$B$21+$B$22+$BW$8 -> #DIV/0! | ... AK24: =+(AK22-$BV$8)*$B$21+$B$22+$BW$8 -> 34.194627 | AL24: =+(AL20-$BV$8)*$B$24+$B$22+$BW$8 -> 27.46319 | AM24: =+(AM20-$BV$8)*$B$24+$B$22+$BW$8 -> 27.231401 | AN24: =+(AN20-$BV$8)*$B$24+$B$22+$BW$8 -> 26.251107 | AO24: =+(AO20-$BV$8)*$B$24+$B$22+$BW$8 -> 25.955953 | AP24: =+(AP20-$BV$8)*$B$24+$B$22+$BW$8 -> 25.972537 | AQ24: =+(AQ20-$BV$8)*$B$24+$B$22+$BW$8 -> 26.580446 | AR24: =+(AR20-$BV$8)*$B$24+$B$22+$BW$8 -> 25.558443 | AS24: =+(AS20-$BV$8)*$B$24+$B$22+$BW$8 -> 24.928012 | ... BR24: =+(BR20-$BV$8)*$B$24+$B$22+$BW$8 -> 460.93261 | BY24: =+BY22+BY23 -> 551.56
BY25: =+BY24/264.172 -> 2.0878821
C26: diff anhydrous/hydrous | AM26: =+AM22-AM20 -> 3.332498 | AN26: =+AN22-AN20 -> 3.2099612 | AO26: =+AO22-AO20 -> 3.1730669 | AP26: =+AP22-AP20 -> 3.1751399 | AQ26: =+AQ22-AQ20 -> 3.2511285 | AR26: =+AR22-AR20 -> 3.1233782 | AS26: =+AS22-AS20 -> 3.0445743 | AT26: =+AT22-AT20 -> 3.0029095 | ... AW26: =+AW22-AW20 -> 3.1453452 | AZ26: =AZ22-AZ12 -> -42.711483 | BA26: =BA22-BA12 -> -43.191819 | BB26: =BB22-BB12 -> -42.645617 | BC26: =BC22-BC12 -> -42.228222 | BK26: =BK12-BK22 -> 23.896442 | BL26: =BL12-BL22 -> 36.471404 | BM26: =BM12-BM22 -> 22.924545 | BN26: =BN12-BN22 -> 25.079935 | BO26: =BO12-BO22 -> 27.235325 | BP26: =BP12-BP22 -> 6.8005567 | BQ26: =BQ12-BQ22 -> -0.38159584 | BR26: =BR12-BR22 -> -6.7794033 | BY26: =+BY25-BK9 -> 0.43288214
BU27: ANH EU | BV27: =750+BW20 -> 774.6098 | BW27: =+BV27/264.172 -> 2.9322176
K28: 44562 | L28: 44593 | M28: 44621 | N28: 44652 | O28: 44682 | P28: 44713 | Q28: 44743 | R28: 44774 | S28: 44805 | T28: 44835 | U28: 44866 | V28: 44896 | W28: 44927 | X28: 44958 | Y28: 44986 | Z28: 45017 | AA28: 45047 | AB28: 45078 | AC28: 45108 | AD28: 45139 | AE28: 45170 | AF28: 45200 | AG28: 45231 | AH28: 45261 | AI28: 45292 | AJ28: 45323 | AK28: 45352 | AL28: 45383 | AM28: 45413 | AN28: 45444 | AO28: 45474 | AP28: 45505 | AQ28: 45536 | AR28: 45566 | AS28: 45597 | AT28: 45627 | AU28: 45658 | AV28: 45689 | AW28: 45717 | AX28: 45748 | AY28: 45778 | AZ28: 45809 | BA28: 45839 | BB28: 45870 | BC28: 45901 | BD28: 45931 | BE28: 45962 | BF28: 45992 | BG28: 46023 | BH28: 46054 | BI28: 46082 | BJ28: 46113 | BK28: 46143 | BL28: 46174 | BM28: 46204 | BN28: 46235 | BO28: 46266 | BP28: 46296 | BQ28: 46327 | BR28: 46357
C29: Grade B ind offer
C30: B3 | K30: =+K16 -> 0 | L30: =+L16 -> 0 | M30: =+M16 -> 0 | N30: =+N16 -> 0 | O30: =+O16 -> 0 | P30: =+P16 -> 0 | Q30: =+Q16 -> 0 | R30: =+R16 -> 0 | ... BR30: =+BR16 -> 2605
B31: 300 | C31: Fobbing | K31: =+$B$31 -> 300 | L31: =+$B$31 -> 300 | M31: =+$B$31 -> 300 | N31: =+$B$31 -> 300 | O31: =+$B$31 -> 300 | P31: =+$B$31 -> 300 | Q31: =+$B$31 -> 300 | R31: =+$B$31 -> 300 | ... BR31: =+$B$31 -> 300
B32: 250 | C32: Premium | K32: =+$B$32 -> 250 | L32: =+$B$32 -> 250 | M32: =+$B$32 -> 250 | N32: =+$B$32 -> 250 | O32: =+$B$32 -> 250 | P32: =+$B$32 -> 250 | Q32: =+$B$32 -> 250 | R32: =+$B$32 -> 250 | ... BR32: =+$B$32 -> 250
B33: =+BV7 -> 44.212219 | C33: Cbios | L33: =+$B$33 -> 44.212219 | M33: =+$B$33 -> 44.212219 | N33: =+$B$33 -> 44.212219 | O33: =+$B$33 -> 44.212219 | P33: =+$B$33 -> 44.212219 | Q33: =+$B$33 -> 44.212219 | R33: =+$B$33 -> 44.212219 | S33: =+$B$33 -> 44.212219 | ... BR33: =+$B$33 -> 44.212219
C34: FOB Sts R$/cbm | K34: =SUM(K30:K32) -> 550 | L34: =SUM(L30:L33) -> 594.21222 | M34: =SUM(M30:M33) -> 594.21222 | N34: =SUM(N30:N33) -> 594.21222 | O34: =SUM(O30:O33) -> 594.21222 | P34: =SUM(P30:P33) -> 594.21222 | Q34: =SUM(Q30:Q33) -> 594.21222 | R34: =SUM(R30:R33) -> 594.21222 | S34: =SUM(S30:S33) -> 594.21222 | ... BR34: =SUM(BR30:BR33) -> 3199.2122
C36: FOB Sts usd/cbm | K36: =+K34/K17 -> #DIV/0! | L36: =+L34/L17 -> #DIV/0! | M36: =+M34/M17 -> #DIV/0! | N36: =+N34/N17 -> #DIV/0! | O36: =+O34/O17 -> #DIV/0! | P36: =+P34/P17 -> #DIV/0! | Q36: =+Q34/Q17 -> #DIV/0! | R36: =+R34/R17 -> #DIV/0! | ... BR36: =+BR34/BR17 -> 535.2282 | BT36: =AVERAGE(Q36:S36) -> #DIV/0! | BU36: =+BT36/264.172 -> #DIV/0!
C37: FOB Sts usd/gal | K37: =+K36/$B$2 -> #DIV/0! | L37: =+L36/$B$2 -> #DIV/0! | M37: =+M36/$B$2 -> #DIV/0! | N37: =+N36/$B$2 -> #DIV/0! | O37: =+O36/$B$2 -> #DIV/0! | P37: =+P36/$B$2 -> #DIV/0! | Q37: =+Q36/$B$2 -> #DIV/0! | R37: =+R36/$B$2 -> #DIV/0! | ... BR37: =+BR36/$B$2 -> 2.0260596
C38: CHIP | K38: =+K9 -> 0 | L38: =+L9 -> 0 | M38: =+M9 -> 0 | N38: =+N9 -> 0 | O38: =+O9 -> 0 | P38: =+P9 -> 0 | Q38: =+Q9 -> 0 | R38: =+R9 -> 0 | ... BR38: =+BR9 -> 1.5825
C39: grade b basis usg | K39: =+K37-K38 -> #DIV/0! | L39: =+L37-L38 -> #DIV/0! | M39: =+M37-M38 -> #DIV/0! | N39: =+N37-N38 -> #DIV/0! | O39: =+O37-O38 -> #DIV/0! | P39: =+P37-P38 -> #DIV/0! | Q39: =+Q37-Q38 -> #DIV/0! | R39: =+R37-R38 -> #DIV/0! | ... BR39: =+BR37-BR38 -> 0.44355955
B41: =+'mkt data'!G18 -> 0.3 | C41: Grade B USA
C42: CHIP | K42: =+K9 -> 0 | L42: =+L9 -> 0 | M42: =+M9 -> 0 | N42: =+N9 -> 0 | O42: =+O9 -> 0 | P42: =+P9 -> 0 | Q42: =+Q9 -> 0 | R42: =+R9 -> 0 | ... BR42: =+BR9 -> 1.5825
C43: FOB USG usd/gal | K43: =+K42+$B$41 -> 0.3 | L43: =+L42+$B$41 -> 0.3 | M43: =+M42+$B$41 -> 0.3 | N43: =+N42+$B$41 -> 0.3 | O43: =+O42+$B$41 -> 0.3 | P43: =+P42+$B$41 -> 0.3 | Q43: =+Q42+$B$41 -> 0.3 | R43: =+R42+$B$41 -> 0.3 | ... BR43: =+BR42+$B$41 -> 1.8825
C44: FOB USG usd/cbm | K44: =+K43*$B$2 -> 79.2516 | L44: =+L43*$B$2 -> 79.2516 | M44: =+M43*$B$2 -> 79.2516 | N44: =+N43*$B$2 -> 79.2516 | O44: =+O43*$B$2 -> 79.2516 | P44: =+P43*$B$2 -> 79.2516 | Q44: =+Q43*$B$2 -> 79.2516 | R44: =+R43*$B$2 -> 79.2516 | ... BR44: =+BR43*$B$2 -> 497.30379
A47: pmt | B47: $/cbm | C47: Anhydrous CIF USGC | L47: 44593 | M47: 44621 | N47: 44652 | O47: 44682 | P47: 44713 | Q47: 44743 | R47: 44774 | S47: 44805 | T47: 44835 | U47: 44866 | V47: 44896 | AB47: pmt | AC47: $/cbm | AD47: 10kcbm = USD 45-48 pmt
A48: 48 | B48: =+A48*$B$3 -> 37.872 | C48: 10kcbm | L48: =+$L$22+B48 -> #DIV/0! | M48: =+$M$22+B48 -> #DIV/0! | N48: =+$N$22+$B$48 -> #DIV/0! | O48: =+$O$22+$B$48 -> #DIV/0! | P48: =+$P$22+$B$48 -> #DIV/0! | Q48: =+$Q$22+$B$48 -> #DIV/0! | R48: =+$R$22+$B$48 -> #DIV/0! | S48: =+$S$22+$B$48 -> #DIV/0! | T48: =+$T$22+$B$48 -> #DIV/0! | U48: =+$U$22+$B$48 -> #DIV/0! | V48: =+$V$22+$B$48 -> #DIV/0! | AB48: 48 | AC48: =+AB48*$B$3 -> 37.872 | AD48: 20kcbm = USD 33-35 pmt
...

Sheet EU
B1: 264.172
B2: 0.789 | BF2: Cbios | BG2: =+'FOB origin'!BW8 -> 10.059106 | BH2: usd/cbm
C3: usd/cbm | AV3: FREIGHT | BC3: pmt | BF3: Export + BonSucro premium | BG3: 0 | BH3: usd/cbm
B4: USA | C4: =+BC4*B2 -> 35.505 | AV4: ST ROSE | BC4: 45 | BF4: Premiun EN Grade USA | BG4: =+'mkt data'!G14 -> 0.27 | BH4: usd/gal | BI4: ='FOB origin'!A12 -> 0.08 | BJ4: =BG4+BI4 -> 0.35
B5: BRZ | C5: =+BC5*B2 -> 43.395 | AV5: SANTOS | BC5: 55 | BF5: T2 CIF discount | BG5: 0 | BH5: eur/cbm
C6: 20000 | BC6: cbm | BF6: EU import duty (den) | BG6: 102 | BH6: eur/cbm
BF7: EU import duty (und) | BG7: 192 | BH7: eur/cbm
C10: CHIP | D10: =+'settlement day'!I9 -> 0 | E10: =+'settlement day'!J9 -> 0 | F10: =+'settlement day'!K9 -> 0 | G10: =+'settlement day'!L9 -> 0 | H10: =+'settlement day'!M9 -> 0 | I10: =+'settlement day'!N9 -> 0 | J10: =+'settlement day'!O9 -> 0 | K10: =+'settlement day'!P9 -> 0 | ... BQ10: =+'settlement day'!BV9 -> 1.5825
D11: JUL | E11: AUG | F11: SEP | G11: OCT | H11: NOV | I11: DEC | J11: JAN | K11: FEB | L11: MAR | M11: APR | N11: MAY | O11: JUN | P11: JUL | Q11: AUG | R11: SEP | S11: OCT | T11: NOV | U11: DEC | V11: JAN | W11: FEB | X11: MAR | Y11: APR | Z11: MAY | AA11: JUN | AB11: JUL | AC11: AUG | AD11: SEP | AE11: OCT | AF11: NOV | AG11: DEC | AH11: JAN | AI11: FEB | AJ11: MAR | AK11: APR | AL11: MAY | AM11: JUN | AN11: JUL | AO11: AUG | AP11: SEP | AQ11: OCT | AR11: NOV | AS11: DEC | AT11: JAN | AU11: FEB | AV11: MAR | AW11: APR | AX11: MAY | AY11: JUN | AZ11: JUL | BA11: AUG | BB11: SEP | BC11: OCT | BD11: NOV | BE11: DEC | BF11: JAN | BG11: FEB | BH11: MAR | BI11: APR | BJ11: MAY | BK11: JUN | BL11: JUL | BM11: AUG | BN11: SEPT | BO11: OCT | BP11: NOV | BQ11: DEC
C12: T2 eur/cbm | D12: =+'settlement day'!I5 -> 0 | E12: =+'settlement day'!J5 -> 0 | F12: =+'settlement day'!K5 -> 0 | G12: =+'settlement day'!L5 -> 0 | H12: =+'settlement day'!M5 -> 0 | I12: =+'settlement day'!N5 -> 0 | J12: =+'settlement day'!O5 -> 0 | K12: =+'settlement day'!P5 -> 0 | ... BQ12: =+'settlement day'!BV5 -> 610
C13: T1 eur/cbm - ind bid | D13: =+D12-$BG$6-$BG$5 -> -102 | E13: =+E12-$BG$6-$BG$5 -> -102 | F13: =+F12-$BG$6-$BG$5 -> -102 | G13: =+G12-$BG$6-$BG$5 -> -102 | H13: =+H12-$BG$6-$BG$5 -> -102 | I13: =+I12-$BG$6-$BG$5 -> -102 | J13: =+J12-$BG$6-$BG$5 -> -102 | K13: =+K12-$BG$6-$BG$5 -> -102 | ... BQ13: =+BQ12-$BG$6-$BG$5 -> 508
C14: eur/usd | D14: =+'settlement day'!I29 -> 0 | E14: =+F14 -> 0 | F14: =+'settlement day'!K29 -> 0 | G14: =+I14 -> 0 | H14: =+I14 -> 0 | I14: =+'settlement day'!O29 -> 0 | J14: =+I14 -> 0 | K14: =+L14 -> 0 | L14: =+'settlement day'!Q29 -> 0 | M14: =+'settlement day'!R29 -> 0 | N14: =+'settlement day'!S29 -> 0 | O14: =+'settlement day'!T29 -> 0 | P14: =+'settlement day'!U29 -> 0 | Q14: =+R14 -> 0 | R14: =+'settlement day'!W29 -> 0 | S14: =+'settlement day'!W29 -> 0 | T14: =+'settlement day'!W29 -> 0 | U14: =+'settlement day'!Z29 -> 0 | V14: =+'settlement day'!AA29 -> 0 | W14: =+'settlement day'!AB29 -> 0 | X14: =+'settlement day'!AC29 -> 0 | Y14: =+'settlement day'!AD29 -> 0 | Z14: =+'settlement day'!AE29 -> 0 | AA14: =+'settlement day'!AF29 -> 0 | AB14: =+'settlement day'!AG29 -> 0 | ... BQ14: =+'settlement day'!BV29 -> 1.1866
C15: T1 usd/cbm - ind bid | D15: =+D14*D13 -> 0 | E15: =+D14*E13 -> 0 | F15: =+F14*F13 -> 0 | G15: =+F14*G13 -> 0 | H15: =+F14*H13 -> 0 | I15: =+I14*I13 -> 0 | J15: =+J14*J13 -> 0 | K15: =+K14*K13 -> 0 | L15: =+L14*L13 -> 0 | M15: =+M14*M13 -> 0 | N15: =+N14*N13 -> 0 | O15: =+O14*O13 -> 0 | P15: =+P14*P13 -> 0 | ... BQ15: =+BQ14*BQ13 -> 602.7928
C18: CIF ARA - shipment from origin
C19: eur/usd | D19: =+'settlement day'!I34 -> 0 | E19: =+F19 -> 0 | F19: =+'settlement day'!K34 -> 0 | G19: =+I19 -> 0 | H19: =+I19 -> 0 | I19: =+'settlement day'!O34 -> 0 | J19: =+I19 -> 0 | K19: =+L19 -> 0 | L19: =+'settlement day'!Q34 -> 0 | M19: =+'settlement day'!R34 -> 0 | N19: =+'settlement day'!S34 -> 0 | O19: =+'settlement day'!T34 -> 0 | P19: =+'settlement day'!U34 -> 0 | Q19: =+R19 -> 0 | R19: =+'settlement day'!W34 -> 0 | S19: =+'settlement day'!W34 -> 0 | T19: =+T14 -> 0 | U19: =+U14 -> 0 | V19: =+V14 -> 0 | W19: =+W14 -> 0 | X19: =+X14 -> 0 | Y19: =+Y14 -> 0 | Z19: =+Z14 -> 0 | AA19: =+AA14 -> 0 | ... BQ19: =+BQ14 -> 1.1866
D20: JUL | E20: AUG | F20: SEP | G20: OCT | H20: NOV | I20: DEC | J20: JAN | K20: FEB | L20: MAR | M20: APR | N20: MAY | O20: JUN | P20: JUL | Q20: AUG | R20: SEP | S20: OCT | T20: NOV | U20: DEC | V20: JAN | W20: FEB | X20: MAR | Y20: APR | Z20: MAY | AA20: JUN | AB20: JUL | AC20: AUG | AD20: SEP | AE20: OCT | AF20: NOV | AG20: DEC | AH20: JAN'24 | AI20: FEB'24 | AJ20: MAR'24 | AK20: APR'24 | AL20: 45413 | AM20: 45444 | AN20: 45474 | AO20: 45505 | AP20: 45536 | AQ20: 45566 | AR20: 45597 | AS20: 45627 | AT20: 45658 | AU20: 45689 | AV20: 45717 | AW20: 45748 | AX20: 45778 | AY20: 45809 | AZ20: 45839 | BA20: 45870 | BB20: 45901 | BC20: 45931 | BD20: 45962 | BE20: 45992 | BF20: 46023 | BG20: 46054 | BH20: 46082 | BI20: 46113 | BJ20: 46143 | BK20: 46174 | BL20: 46204 | BM20: 46235 | BN20: 46266 | BO20: 46296 | BP20: 46327 | BQ20: 46357
C21: T2 eur/cbm flat | D21: =+D12-$BG$5 -> 0 | E21: =+E12-$BG$5 -> 0 | F21: =+F12-$BG$5 -> 0 | G21: =+G12-$BG$5 -> 0 | H21: =+H12-$BG$5 -> 0 | I21: =+I12-$BG$5 -> 0 | J21: =+J12-$BG$5-$BI$5 -> 0 | K21: =+K12-$BG$5-$BI$5 -> 0 | L21: =+L12-$BG$5-$BI$5 -> 0 | M21: =+M12-$BG$5-$BI$5 -> 0 | N21: =+N12-$BG$5-$BI$5 -> 0 | O21: =+O12-$BG$5-$BI$5 -> 0 | P21: =+P12-$BG$5-$BI$5 -> 0 | Q21: =+Q12-$BG$5-$BI$5 -> 0 | ... BQ21: =+BQ12-$BG$5-$BI$5 -> 610
C22: D-1 | H22: =+'settlement day'!M7 -> 0 | I22: =+'settlement day'!N7 -> 0 | J22: =+'settlement day'!O7 -> 0 | K22: =+'settlement day'!P7 -> 0 | L22: =+'settlement day'!Q7 -> 0 | M22: =+'settlement day'!R7 -> 0 | N22: =+'settlement day'!S7 -> 0 | O22: =+'settlement day'!T7 -> 0 | ... BQ22: =+'settlement day'!BV7 -> 6
C23: BRZ Origin
C24: Anhydrous BS FOB usd/cbm | D24: =+'FOB origin'!E22+$BG$3 -> #DIV/0! | E24: =+'FOB origin'!F22+$BG$3 -> #DIV/0! | F24: =+'FOB origin'!G22+$BG$3 -> #DIV/0! | G24: =+'FOB origin'!H22+$BG$3 -> #DIV/0! | H24: =+'FOB origin'!I22+$BG$3 -> #DIV/0! | I24: =+'FOB origin'!J22+$BG$3 -> #DIV/0! | J24: =+'FOB origin'!K22+$BG$3 -> #DIV/0! | K24: =+'FOB origin'!L22+$BG$3 -> #DIV/0! | ... BQ24: =+'FOB origin'!BR22+$BG$3 -> 517.29179
C25: CIF ARA - T1 usd/cbm | D25: =+D24+$C$5 -> #DIV/0! | E25: =+E24+$C$5 -> #DIV/0! | F25: =+F24+$C$5 -> #DIV/0! | G25: =+G24+$C$5 -> #DIV/0! | H25: =+H24+$C$5 -> #DIV/0! | I25: =+I24+$C$5 -> #DIV/0! | J25: =+J24+$C$5 -> #DIV/0! | K25: =+K24+$C$5 -> #DIV/0! | ... BQ25: =+BQ24+$C$5 -> 560.68679
C26: CIF ARA eur/cbm T2 DEN. | D26: =+(D25/D14)+$BG$6 -> #DIV/0! | E26: =+(E25/E14)+$BG$6 -> #DIV/0! | F26: =+(F25/F14)+$BG$6 -> #DIV/0! | G26: =+(G25/G14)+$BG$6 -> #DIV/0! | H26: =+(H25/H14)+$BG$6 -> #DIV/0! | I26: =+(I25/I14)+$BG$6 -> #DIV/0! | J26: =+(J25/J14)+$BG$6 -> #DIV/0! | K26: =+(K25/K14)+$BG$6 -> #DIV/0! | ... BQ26: =+(BQ25/BQ14)+$BG$6 -> 574.51542
C27: BRZ DEN Arb M0 vs T2 M+1 | T27: =+U21-T26 -> #DIV/0! | U27: =+V21-U26 -> #DIV/0! | V27: =+W21-V26 -> #DIV/0! | W27: =+X21-W26 -> #DIV/0! | X27: =+Y21-X26 -> #DIV/0! | Y27: =+Z21-Y26 -> #DIV/0! | Z27: =+AA21-Z26 -> #DIV/0! | AA27: =+AB21-AA26 -> #DIV/0! | ... BG27: =+BH21-BG26 -> -47.058113 | BH27: =+BI12-BH26 -> -35.683379 | BI27: =+BJ12-BI26 -> 16.500207 | BJ27: =+BK12-BJ26 -> 66.777555 | BK27: =+BL12-BK26 -> 69.64988 | BL27: =+BM12-BL26 -> 56.859768 | BM27: =+BN12-BM26 -> 57.799514 | BN27: =+BO12-BN26 -> 49.73926 | BO27: =+BP12-BO26 -> 34.684398 | BP27: =+BQ12-BP26 -> 35.867136 | BQ27: =+BQ12-BQ26 -> 35.484583
C28: **CIF ARA eur/cbm T2 DEN. | D28: =+(D26/D15)+$BG$6 -> #DIV/0! | E28: =+(E26/E15)+$BG$6 -> #DIV/0! | F28: =+(F26/F15)+$BG$6 -> #DIV/0! | G28: =+(G26/G15)+$BG$6 -> #DIV/0! | H28: =+(H26/H15)+$BG$6 -> #DIV/0! | I28: =+(I26/I15)+$BG$6 -> #DIV/0! | J28: =+(J26/J15)+$BG$6 -> #DIV/0! | K28: =+(K26/K15)+$BG$6 -> #DIV/0! | ... AJ28: =+(AJ26/AJ15)+$BG$6 -> 100.45662 | AK28: =((('FOB origin'!AL24+EU!$C$5)/AK14)+$BG$6) -> 168.11139 | AL28: =((('FOB origin'!AM24+EU!$C$5)/AL14)+$BG$6) -> 167.08146 | AM28: =((('FOB origin'!AN24+EU!$C$5)/AM14)+$BG$6) -> 167.05942 | AN28: =((('FOB origin'!AO24+EU!$C$5)/AN14)+$BG$6) -> 166.0478 | AO28: =((('FOB origin'!AP24+EU!$C$5)/AO14)+$BG$6) -> 164.86138 | AP28: =((('FOB origin'!AQ24+EU!$C$5)/AP14)+$BG$6) -> 164.5004 | AQ28: =((('FOB origin'!AR24+EU!$C$5)/AQ14)+$BG$6) -> 165.36468 | AR28: =((('FOB origin'!AS24+EU!$C$5)/AR14)+$BG$6) -> 166.68757 | ... BQ28: =((('FOB origin'!BR24+EU!$C$5)/BQ14)+$BG$6) -> 527.01905
C29: **BRZ DEN Arb M0 vs T2 M+1 | AK29: =+AL21-AK28 -> -168.11139 | AL29: =+AM21-AL28 -> -167.08146 | AM29: =+AN21-AM28 -> -167.05942 | AN29: =+AO21-AN28 -> -166.0478 | AO29: =+AP21-AO28 -> -164.86138 | AP29: =+AQ21-AP28 -> -164.5004 | AQ29: =+AR21-AQ28 -> -165.36468 | AR29: =+AS21-AR28 -> -166.68757 | ... AU29: =+AV21-AU28 -> -168.12569 | AV29: =+AV21-AV28 -> -165.91972 | AW29: =+AW21-AW28 -> -162.9818 | AX29: =+AX21-AX28 -> -163.04698 | AY29: =+AY21-AY28 -> -161.68276 | AZ29: =+AZ21-AZ28 -> -162.73845 | BA29: =+BA21-BA28 -> -161.75821 | BB29: =+BB21-BB28 -> -161.94188 | BC29: =+BC21-BC28 -> 168.75768 | ... BQ29: =+BQ21-BQ28 -> 82.980949
C30: US Origin
C31: FOB IMTT usd/cbm (M0) | D31: =+(D10+$BG$4)*$B$1 -> 71.32644 | E31: =+(E10+$BG$4)*$B$1 -> 71.32644 | F31: =+(F10+$BG$4)*$B$1 -> 71.32644 | G31: =+(G10+$BG$4)*$B$1 -> 71.32644 | H31: =+(H10+$BG$4)*$B$1 -> 71.32644 | I31: =+(I10+$BG$4)*$B$1 -> 71.32644 | J31: =+(J10+$BG$4)*$B$1 -> 71.32644 | K31: =+(K10+$BG$4)*$B$1 -> 71.32644 | ... BE31: =+(BE10+$BG$4)*$B$1 -> 501.9268 | BF31: =+(BF10+$BG$4+$BI$4)*$B$1 -> 509.19153 | BG31: =+(BG10+$BG$4+$BI$4)*$B$1 -> 510.51239 | BH31: =+(BH10+$BG$4+$BI$4)*$B$1 -> 517.11669 | BI31: =+(BI10+$BG$4+$BI$4)*$B$1 -> 523.72099 | BJ31: =+(BJ10+$BG$4+$BI$4)*$B$1 -> 529.66486 | BK31: =+(BK10+$BG$4+$BI$4)*$B$1 -> 532.96701 | BL31: =+(BL10+$BG$4+$BI$4)*$B$1 -> 534.28787 | BM31: =+(BM10+$BG$4+$BI$4)*$B$1 -> 532.96701 | ... BQ31: =+(BQ10+$BG$4+$BI$4)*$B$1 -> 510.51239
C32: CIF ARA - T1 usd/cbm | D32: =+D31+$C$4 -> 106.83144 | E32: =+E31+$C$4 -> 106.83144 | F32: =+F31+$C$4 -> 106.83144 | G32: =+G31+$C$4 -> 106.83144 | H32: =+H31+$C$4 -> 106.83144 | I32: =+I31+$C$4 -> 106.83144 | J32: =+J31+$C$4 -> 106.83144 | K32: =+K31+$C$4 -> 106.83144 | ... BQ32: =+BQ31+$C$4 -> 546.01739
C33: CIF ARA eur/cbm T2 DEN. | D33: =+(D32/D14)+$BG$6 -> #DIV/0! | E33: =+(E32/E14)+$BG$6 -> #DIV/0! | F33: =+(F32/F14)+$BG$6 -> #DIV/0! | G33: =+(G32/G14)+$BG$6 -> #DIV/0! | H33: =+(H32/H14)+$BG$6 -> #DIV/0! | I33: =+(I32/I14)+$BG$6 -> #DIV/0! | J33: =+(J32/J14)+$BG$6 -> #DIV/0! | K33: =+(K32/K14)+$BG$6 -> #DIV/0! | ... BQ33: =+(BQ32/BQ14)+$BG$6 -> 562.15287
C34: USA DEN Arb M0 vs T2 M+1 | T34: =+U26-T33 -> #DIV/0! | U34: =+V21-U33 -> #DIV/0! | V34: =+W21-V33 -> #DIV/0! | W34: =+X21-W33 -> #DIV/0! | X34: =+Y21-X33 -> #DIV/0! | Y34: =+Z21-Y33 -> #DIV/0! | Z34: =+AA21-Z33 -> #DIV/0! | AA34: =+AB21-AA33 -> #DIV/0! | AB34: =+AC21-AB33 -> #DIV/0! | ... BE34: =+BF21-BE33 -> 43.733703 | BF34: =+BF21-BF33 -> 38.389029 | BG34: =+BG21-BG33 -> 45.798181 | BH34: =+BI12-BH33 -> 62.183473 | BI34: =+BJ12-BI33 -> 58.234748 | BJ34: =+BK12-BJ33 -> 53.18859 | BK34: =+BL12-BK33 -> 45.385169 | BL34: =+BM12-BL33 -> 44.145564 | BM34: =+BN12-BM33 -> 43.262571 | BN34: =+BO12-BN33 -> 33.379577 | BO34: =+BP12-BO33 -> 35.60252 | BP34: =+BQ12-BP33 -> 42.837974 | BQ34: =+BQ12-BQ33 -> 47.847135
B36: 1.25 | AV36: =AV32*$B$36 -> 133.5393 | AW36: =AW32*$B$36 -> 133.5393 | AX36: =AX32*$B$36 -> 133.5393 | AY36: =AY32*$B$36 -> 133.5393 | AZ36: =AZ32*$B$36 -> 133.5393 | BA36: =BA32*$B$36 -> 133.5393 | BB36: =BB32*$B$36 -> 133.5393 | BC36: =BC32*$B$36 -> 734.5306 | ... BQ36: =BQ32*$B$36 -> 682.52174
C37: USD vs BRZ | AV37: =AV36-AV25 -> 62.450737 | AW37: =AW36-AW25 -> 62.197134 | AX37: =AX36-AX25 -> 62.347243 | AY37: =AY36-AY25 -> 61.529343 | AZ37: =AZ36-AZ25 -> 62.009679 | BA37: =BA36-BA25 -> 61.463477 | BB37: =BB36-BB25 -> 61.046082 | BC37: =BC36-BC25 -> 73.843937 | ... BQ37: =BQ36-BQ25 -> 121.83494
AV38: =AV37/264.172 -> 0.2364018 | AW38: =AW37/264.172 -> 0.23544181 | AX38: =AX37/264.172 -> 0.23601003 | AY38: =AY37/264.172 -> 0.23291395 | AZ38: =AZ37/264.172 -> 0.23473221 | BA38: =BA37/264.172 -> 0.23266462 | BB38: =BB37/264.172 -> 0.2310846 | BC38: =BC37/264.172 -> 0.27952977 | ... BQ38: =BQ37/264.172 -> 0.46119552
C39: ** Anhydrous flat Hydrous
BB40: 45901 | BC40: 45931 | BD40: 45962 | BE40: 45992 | BF40: 46023 | BG40: 46054 | BH40: 46082 | BI40: 46113 | BJ40: 46143 | BK40: 46174 | BL40: 46204 | BM40: 46235 | BN40: 46266 | BO40: 46296 | BP40: 46327 | BQ40: 46357
C41: ARB FAVORABLE TO: | BC41: =IF(BC26>BC33, "USA", "BRZ") -> USA | BD41: =IF(BD26>BD33, "USA", "BRZ") -> USA | BE41: =IF(BE26>BE33, "USA", "BRZ") -> USA | BF41: =IF(BF26>BF33, "USA", "BRZ") -> USA | BG41: =IF(BG26>BG33, "USA", "BRZ") -> USA | BH41: =IF(BH26>BH33, "USA", "BRZ") -> USA | BI41: =IF(BI26>BI33, "USA", "BRZ") -> USA | BJ41: =IF(BJ26>BJ33, "USA", "BRZ") -> BRZ | ... BQ41: =IF(BQ26>BQ33, "USA", "BRZ") -> USA
C43: Brazil premium over USA | AI43: =AI26-AI33 -> -30.534847 | AJ43: =AJ26-AJ33 -> -30.62575 | AK43: =AK26-AK33 -> -31.533625 | AL43: =AL26-AL33 -> -31.384539 | AM43: =AM26-AM33 -> -32.84571 | AN43: =AN26-AN33 -> -32.779259 | AO43: =AO26-AO33 -> -32.147462 | AP43: =AP26-AP33 -> -31.074336 | ... BQ43: =BQ26-BQ33 -> 12.362551
BB44: =BB43/264.172 -> -0.11070976 | BC44: =BC43/264.172 -> 0.23741995 | BD44: =BD43/264.172 -> 0.37359548 | BE44: =BE43/264.172 -> 0.41468438 | BF44: =BF43/264.172 -> 0.39363973 | BG44: =BG43/264.172 -> 0.3893535 | BH44: =BH43/264.172 -> 0.37046641 | BI44: =BI43/264.172 -> 0.15798245 | ... BQ44: =BQ43/264.172 -> 0.046797357
C46: T2 M+1 eur/cbm disc | K46: =+L10 -> 0 | L46: =+M10 -> 0 | M46: =+N10 -> 0 | N46: =+O10 -> 0 | O46: =+P10 -> 0 | P46: =+Q10 -> 0 | Q46: =+R21+$C$47 -> -130 | R46: =+S21+$C$47 -> -130 | S46: =+T21+$C$47 -> -130 | T46: =+U21+$C$47 -> -130 | U46: =+V21+$C$47 -> -130 | V46: =+W21+$C$47 -> -130 | W46: =+X21+$C$47 -> -130 | X46: =+Y21+$C$47 -> -130 | ... BQ46: =+BR21+$C$47 -> -130
C47: -130
...

Sheet ARB BRZ 2022
A1: 0.789 | E1: =+'settlement day'!M30 -> 0
A2: 264.172 | C2: FX | D2: =+'settlement day'!M30 -> 0 | E2: =+'settlement day'!N30 -> 0 | F2: =+'settlement day'!O30 -> 0 | G2: =+'settlement day'!P30 -> 0 | H2: =+'settlement day'!Q30 -> 0 | I2: =+'settlement day'!R30 -> 0 | J2: =+'settlement day'!S30 -> 0 | K2: =+'settlement day'!T30 -> 0 | ... T2: =+'settlement day'!AC30 -> 0
D3: 44501 | E3: 44531 | F3: 44562 | G3: 44593 | H3: 44621 | I3: 44652 | J3: 44682 | K3: 44713 | L3: 44743 | M3: 44774 | N3: 44805 | O3: 44835 | P3: 44866 | Q3: 44896 | R3: 44927 | S3: 44958 | T3: 44986
C4: CHIP | D4: =+'settlement day'!M9 -> 0 | E4: =+'settlement day'!N9 -> 0 | F4: =+'settlement day'!O9 -> 0 | G4: =+'settlement day'!P9 -> 0 | H4: =+'settlement day'!Q9 -> 0 | I4: =+'settlement day'!R9 -> 0 | J4: =+'settlement day'!S9 -> 0 | K4: =+'settlement day'!T9 -> 0 | ... T4: =+'settlement day'!AC9 -> 0
B5: 0.13 | C5: FOB (usd/gal) | D5: =+D4+$B$5 -> 0.13 | E5: =+E4+$B$5 -> 0.13 | F5: =+F4+$B$5 -> 0.13 | G5: =+G4+$B$5 -> 0.13 | H5: =+H4+$B$5 -> 0.13 | I5: =+I4+$B$5 -> 0.13 | J5: =+J4+$B$5 -> 0.13 | K5: =+K4+$B$5 -> 0.13 | ... T5: =+T4+$B$5 -> 0.13
C6: FOB usd/cbm | D6: =+D5*$A$2 -> 34.34236 | E6: =+E5*$A$2 -> 34.34236 | F6: =+F5*$A$2 -> 34.34236 | G6: =+G5*$A$2 -> 34.34236 | H6: =+H5*$A$2 -> 34.34236 | I6: =+I5*$A$2 -> 34.34236 | J6: =+J5*$A$2 -> 34.34236 | K6: =+K5*$A$2 -> 34.34236 | ... T6: =+T5*$A$2 -> 34.34236
B8: 0.02 | C8: cost (usd/cbm) | D8: =+$B$8*$A$2 -> 5.28344 | E8: =+D8 -> 5.28344 | F8: =+E8 -> 5.28344 | G8: =+F8 -> 5.28344 | H8: =+G8 -> 5.28344 | I8: =+H8 -> 5.28344 | J8: =+I8 -> 5.28344 | K8: =+J8 -> 5.28344 | L8: =+K8 -> 5.28344 | ... T8: =+S8 -> 5.28344
A9: 20kcbm | B9: 85 | C9: freight usd/cbm | D9: =+$B$9*$A$1 -> 67.065 | E9: =+D9 -> 67.065 | F9: =+E9 -> 67.065 | G9: =+F9 -> 67.065 | H9: =+G9 -> 67.065 | I9: =+H9 -> 67.065 | J9: =+I9 -> 67.065 | K9: =+J9 -> 67.065 | L9: =+K9 -> 67.065 | ... T9: =+S9 -> 67.065
C10: CIF usd/cbm | D10: =SUM(D6:D9) -> 106.6908 | E10: =SUM(E6:E9) -> 106.6908 | F10: =SUM(F6:F9) -> 106.6908 | G10: =SUM(G6:G9) -> 106.6908 | H10: =SUM(H6:H9) -> 106.6908 | I10: =SUM(I6:I9) -> 106.6908 | J10: =SUM(J6:J9) -> 106.6908 | K10: =SUM(K6:K9) -> 106.6908 | ... T10: =SUM(T6:T9) -> 106.6908
C11: CIF brl/cbm | E11: =+E10*E2 -> 0 | F11: =+F10*F2 -> 0 | G11: =+G10*G2 -> 0 | H11: =+H10*H2 -> 0 | I11: =+I10*I2 -> 0 | J11: =+J10*J2 -> 0 | K11: =+K10*K2 -> 0 | L11: =+L10*L2 -> 0 | ... T11: =+T10*T2 -> 0
B13: 0 | C13: Import duly | D13: =+D10*$B$13 -> 0 | E13: =+E11*$B$13 -> 0 | F13: =+F11*$B$13 -> 0 | G13: =+G11*$B$13 -> 0 | H13: =+H11*$B$13 -> 0 | I13: =+I11*$B$13 -> 0 | J13: =+J11*$B$13 -> 0 | K13: =+K11*$B$13 -> 0 | L13: =+L11*$B$13 -> 0 | ... T13: =+T11*$B$13 -> 0
A14: antes 11.75% | B14: 0 | C14: PIS/COFINS | D14: =+D10*$B$14 -> 0 | E14: =+E11*$B$14 -> 0 | F14: =+F11*$B$14 -> 0 | G14: =+G11*$B$14 -> 0 | H14: =+H11*$B$14 -> 0 | I14: =+I11*$B$14 -> 0 | J14: =+J11*$B$14 -> 0 | K14: =+K11*$B$14 -> 0 | L14: =+L11*$B$14 -> 0 | ... T14: =+T11*$B$14 -> 0
C15: ICMS | D15: 0 | E15: 0 | F15: 0 | G15: 0 | H15: 0 | I15: 0 | J15: 0 | K15: 0 | L15: 0 | M15: 0 | N15: 0 | O15: 0 | P15: 0 | Q15: 0 | R15: 1 | S15: 2 | T15: 3
B16: 0.08 | C16: AFRMM | D16: 0 | E16: 0 | F16: 0 | G16: 0 | H16: =+H9*$B$16 -> 5.3652 | I16: =+I9*$B$16 -> 5.3652 | J16: =+J9*$B$16 -> 5.3652 | K16: =+K9*$B$16 -> 5.3652 | L16: =+L9*$B$16 -> 5.3652 | M16: =+M9*$B$16 -> 5.3652 | N16: =+N9*$B$16 -> 5.3652 | O16: =+O9*$B$16 -> 5.3652 | ... T16: =+T9*$B$16 -> 5.3652
C17: Cargo Cleared usd/cbm | D17: =SUM(D10:D16) -> 106.6908 | E17: =SUM(E11:E16) -> 0 | F17: =SUM(F11:F16) -> 0 | G17: =SUM(G11:G16) -> 0 | H17: =SUM(H11:H16) -> 5.3652 | I17: =SUM(I11:I16) -> 5.3652 | J17: =SUM(J11:J16) -> 5.3652 | K17: =SUM(K11:K16) -> 5.3652 | L17: =SUM(L11:L16) -> 5.3652 | ... T17: =SUM(T11:T16) -> 8.3652
C19: Terminal cost (brl/cbm) | D19: 80 | E19: 80 | F19: 80 | G19: 80 | H19: 80 | I19: 80 | J19: 80 | K19: 80 | L19: 80 | M19: 80 | N19: 80 | O19: 80 | P19: 80 | Q19: 80 | R19: 80 | S19: 80 | T19: 80
C20: Inspection (brl/cbm) | D20: 15 | E20: 15 | F20: 15 | G20: 15 | H20: 15 | I20: 15 | J20: 15 | K20: 15 | L20: 15 | M20: 15 | N20: 15 | O20: 15 | P20: 15 | Q20: 15 | R20: 15 | S20: 15 | T20: 15
C21: Inland freight (brl/cbm) | D21: 25 | E21: 25 | F21: 25 | G21: 25 | H21: 25 | I21: 25 | J21: 25 | K21: 25 | L21: 25 | M21: 25 | N21: 25 | O21: 25 | P21: 25 | Q21: 25 | R21: 25 | S21: 25 | T21: 25
C22: Other costs (brl/cbm)
C23: Margin (brl/cbm)
C25: EX Tank disport (brl/cbm) | D25: =SUM(D19:D24) -> 120 | E25: =SUM(E17:E24) -> 120 | F25: =SUM(F17:F24) -> 120 | G25: =SUM(G17:G24) -> 120 | H25: =SUM(H17:H24) -> 125.3652 | I25: =SUM(I17:I24) -> 125.3652 | J25: =SUM(J17:J24) -> 125.3652 | K25: =SUM(K17:K24) -> 125.3652 | L25: =SUM(L17:L24) -> 125.3652 | ... T25: =SUM(T17:T24) -> 128.3652
C26: EX Tank disport (usd/cbm) | E26: =+E25/E2 -> #DIV/0! | F26: =+F25/F2 -> #DIV/0! | G26: =+G25/G2 -> #DIV/0! | H26: =+H25/H2 -> #DIV/0! | I26: =+I25/I2 -> #DIV/0! | J26: =+J25/J2 -> #DIV/0! | K26: =+K25/K2 -> #DIV/0! | L26: =+L25/L2 -> #DIV/0! | ... T26: =+T25/T2 -> #DIV/0!
C28: NE BRZ (brl/cbm) | D28: =+'PLATTS&OPIS'!I156 -> 4470 | E28: =+'PLATTS&OPIS'!I171 -> 4480 | G28: =+'PLATTS&OPIS'!I236 -> 3565 | H28: =+'PLATTS&OPIS'!I266 -> 4150 | I28: =+'PLATTS&OPIS'!I285 -> 4195 | J28: =+'PLATTS&OPIS'!I305 -> 4445 | K28: =+'PLATTS&OPIS'!I330 -> 4045 | L28: =+'PLATTS&OPIS'!I350 -> 4095 | M28: =+'PLATTS&OPIS'!I370 -> 3495 | N28: =+'PLATTS&OPIS'!I400 -> 3160 | O28: =+'PLATTS&OPIS'!I415 -> 3245 | P28: =+'PLATTS&OPIS'!I579 -> 3595 | Q28: =+P28 -> 3595 | R28: =+Q28 -> 3595 | S28: =+R28 -> 3595 | T28: =+S28 -> 3595
C29: 0% import tax | D29: 44501 | E29: 44531 | F29: 44562 | G29: 44593 | H29: 44621 | I29: 44652 | J29: 44682 | K29: 44713 | L29: 44743 | M29: 44774 | N29: 44805 | O29: 44835 | P29: 44866 | Q29: 44896 | R29: 44927 | S29: 44958 | T29: 44986
C30: ARB (brl/cbm) | D30: =+D28-D25 -> 4350 | E30: =+E28-E25 -> 4360 | F30: =+F28-F25 -> -120 | G30: =+G28-G25 -> 3445 | H30: =+H28-H25 -> 4024.6348 | I30: =+I28-I25 -> 4069.6348 | J30: =+J28-J25 -> 4319.6348 | K30: =+K28-K25 -> 3919.6348 | ... T30: =+T28-T25 -> 3466.6348
C31: ARB (usd/cbm) | D31: =+D30/$E$1 -> #DIV/0! | E31: =+E30/E2 -> #DIV/0! | F31: =+F30/F2 -> #DIV/0! | G31: =+G30/G2 -> #DIV/0! | H31: =+H30/H2 -> #DIV/0! | I31: =+I30/I2 -> #DIV/0! | J31: =+J30/J2 -> #DIV/0! | K31: =+K30/K2 -> #DIV/0! | L31: =+L30/L2 -> #DIV/0! | ... T31: =+T30/T2 -> #DIV/0!
C32: ARB (usd/gal) | H32: =+H31/264.172 -> #DIV/0! | I32: =+I31/264.172 -> #DIV/0! | J32: =+J31/264.172 -> #DIV/0! | K32: =+K31/264.172 -> #DIV/0! | L32: =+L31/264.172 -> #DIV/0! | M32: =+M31/264.172 -> #DIV/0! | N32: =+N31/264.172 -> #DIV/0! | O32: =+O31/264.172 -> #DIV/0! | ... T32: =+T31/264.172 -> #DIV/0!
C34: load mth+1 | D34: 44531 | E34: 44562 | F34: 44593 | G34: 44621 | I34: 44652 | J34: 44682 | K34: 44713 | L34: 44743 | M34: 44774 | N34: 44805 | O34: 44835 | P34: 44866 | Q34: 44896 | R34: 44927 | S34: 44958 | T34: 44986
C35: B3 hyd | D35: =+'settlement day'!N13 -> 0 | E35: =+'settlement day'!O13 -> 0 | F35: =+'settlement day'!P13 -> 0 | G35: =+'settlement day'!Q13 -> 0 | I35: =+'settlement day'!R13 -> 0 | J35: =+'settlement day'!S13 -> 0 | K35: =+'settlement day'!T13 -> 0 | L35: =+'settlement day'!U13 -> 0 | M35: =+'settlement day'!V13 -> 0 | N35: =+'settlement day'!W13 -> 0 | O35: =+'settlement day'!X13 -> 0 | P35: =+'settlement day'!Y13 -> 0 | ... T35: =+'settlement day'!AC13 -> 0
